Workbook

Sheet FishInfo
A1: Id | B1: FishGroupId | C1: FishType | D1: FGroupName | E1: FName | F1: Order | G1: TargetPool | H1: IsFixedScale | I1: FixedScale | J1: BookScale | K1: FishTargetDistance | L1: FishZoomDistance | M1: FishName | N1: FishIcon | O1: PrefabPath
A2: int | B2: int | C2: fishtype | D2: string | E2: string | F2: int | G2: string | H2: int | I2: int | J2: int | K2: int | L2: int | M2: string | N2: string | O2: string
A3: client | B3: all | C3: all | D3: nodata | E3: nodata | F3: client | G3: client | H3: client | I3: client | J3: client | K3: client | L3: client | M3: client | N3: client | O3: client
A4: 1 | B4: 0 | C4: 1 | D4: =IFERROR(INDEX(FishGroup!$B$4:$B$31,MATCH(B4,FishGroup!$A$4:$A$31,0)),"기타") -> 크라운 | E4: 퍼큘라 크라운 | F4: 10 | G4: 0_SmallFishContainerA | H4: 0 | I4: 100 | J4: 100 | K4: 500 | L4: 250 | M4: fishname_ClownFish | N4: fish_ClownFish | O4: Fish/clownfish
A5: 2 | B5: 0 | C5: 1 | D5: =IFERROR(INDEX(FishGroup!$B$4:$B$31,MATCH(B5,FishGroup!$A$4:$A$31,0)),"기타") -> 크라운 | E5: 레드 크라운 | F5: 20 | G5: 0_SmallFishContainerA | H5: 0 | I5: 100 | J5: 100 | K5: 500 | L5: 250 | M5: fishname_Red ClownFish | N5: fish_Red ClownFish | O5: Fish/red_clownfish
A6: 3 | B6: 0 | C6: 2 | D6: =IFERROR(INDEX(FishGroup!$B$4:$B$31,MATCH(B6,FishGroup!$A$4:$A$31,0)),"기타") -> 크라운 | E6: 블루 크라운 | F6: 30 | G6: 0_SmallFishContainerA | H6: 0 | I6: 100 | J6: 100 | K6: 500 | L6: 250 | M6: fishname_Blue ClownFish | N6: fish_Blue ClownFish | O6: Fish/blue_clownfish
A7: 4 | B7: 0 | C7: 2 | D7: =IFERROR(INDEX(FishGroup!$B$4:$B$31,MATCH(B7,FishGroup!$A$4:$A$31,0)),"기타") -> 크라운 | E7: 스노우플레이크 크라운 | F7: 40 | G7: 0_SmallFishContainerA | H7: 0 | I7: 100 | J7: 100 | K7: 500 | L7: 250 | M7: fishname_Snow Clown | N7: fish_Snow Clown | O7: Fish/4_Snowfrake clown
A8: 5 | B8: 1 | C8: 1 | D8: =IFERROR(INDEX(FishGroup!$B$4:$B$31,MATCH(B8,FishGroup!$A$4:$A$31,0)),"기타") -> 고비 | E8: 파이어 고비 | F8: 50 | G8: 0_SmallFishContainerB | H8: 0 | I8: 100 | J8: 100 | K8: 500 | L8: 250 | M8: fishname_Fire Goby | N8: fish_Fire Goby | O8: Fish/fire_goby
A9: 6 | B9: 1 | C9: 1 | D9: =IFERROR(INDEX(FishGroup!$B$4:$B$31,MATCH(B9,FishGroup!$A$4:$A$31,0)),"기타") -> 고비 | E9: 블루 밴디드 고비 | F9: 60 | G9: 0_SmallFishContainerB | H9: 0 | I9: 100 | J9: 100 | K9: 500 | L9: 250 | M9: fishname_Blue Banded Goby | N9: fish_Blue Banded Goby | O9: Fish/blue_banded_goby
A10: 7 | B10: 1 | C10: 1 | D10: =IFERROR(INDEX(FishGroup!$B$4:$B$31,MATCH(B10,FishGroup!$A$4:$A$31,0)),"기타") -> 고비 | E10: 헬프리치 고비 | F10: 70 | G10: 0_SmallFishContainerB | H10: 0 | I10: 100 | J10: 100 | K10: 500 | L10: 250 | M10: fishname_Helfrich Goby | N10: fish_Helfrich Goby | O10: Fish/helfrich_goby
A11: 8 | B11: 1 | C11: 2 | D11: =IFERROR(INDEX(FishGroup!$B$4:$B$31,MATCH(B11,FishGroup!$A$4:$A$31,0)),"기타") -> 고비 | E11: 랜달스 고비 | F11: 80 | G11: 0_SmallFishContainerB | H11: 0 | I11: 100 | J11: 100 | K11: 500 | L11: 250 | M11: fishname_Randalls Goby | N11: fish_Randalls Goby | O11: Fish/13_Randalls Goby
A12: 9 | B12: 1 | C12: 1 | D12: =IFERROR(INDEX(FishGroup!$B$4:$B$31,MATCH(B12,FishGroup!$A$4:$A$31,0)),"기타") -> 고비 | E12: 시저테일 고비 | F12: 90 | G12: 0_SmallFishContainerB | H12: 0 | I12: 100 | J12: 100 | K12: 500 | L12: 250 | M12: fishname_Scissortail Goby | N12: fish_Scissortail Goby | O12: Fish/14_Scissortail Goby
A13: 10 | B13: 1 | C13: 1 | D13: =IFERROR(INDEX(FishGroup!$B$4:$B$31,MATCH(B13,FishGroup!$A$4:$A$31,0)),"기타") -> 고비 | E13: 옐로 와치맨 고비 | F13: 100 | G13: 0_SmallFishContainerB | H13: 0 | I13: 100 | J13: 100 | K13: 500 | L13: 250 | M13: fishname_Yellow Watchman Goby | N13: fish_Yellow Watchman Goby | O13: Fish/yellow_watchman_goby
A14: 11 | B14: 2 | C14: 1 | D14: =IFERROR(INDEX(FishGroup!$B$4:$B$31,MATCH(B14,FishGroup!$A$4:$A$31,0)),"기타") -> 탱 | E14: 블루탱 | F14: 110 | G14: 1_LargeFishContainerA | H14: 0 | I14: 100 | J14: 80 | K14: 500 | L14: 250 | M14: fishname_Blue Tang | N14: fish_Blue Tang | O14: Fish/blue_tang
A15: 12 | B15: 2 | C15: 1 | D15: =IFERROR(INDEX(FishGroup!$B$4:$B$31,MATCH(B15,FishGroup!$A$4:$A$31,0)),"기타") -> 탱 | E15: 아킬레스 탱 | F15: 120 | G15: 1_LargeFishContainerA | H15: 0 | I15: 100 | J15: 75 | K15: 500 | L15: 250 | M15: fishname_Achilles Tang | N15: fish_Achilles Tang | O15: Fish/17_Achilles Tang
... A233: 230 | B233: 999 | C233: 4 | D233: =IFERROR(INDEX(FishGroup!$B$4:$B$31,MATCH(B233,FishGroup!$A$4:$A$31,0)),"기타") -> 기타 | E233: 코기 | F233: 1252 | G233: 2_UniqueFishContainerA | H233: 0 | I233: 100 | J233: 60 | K233: 600 | L233: 400 | M233: fishname_Corgi | N233: fish_Corgi | O233: Fish/226_Corgi

Sheet FishUnlockCondition
A1: Id | B1: FishId | C1: Order | D1: UnlockType | E1: UnlockTarget | F1: UnlockValue | G1: UnlockDesc | H1: FName | I1: GroupName | J1: test_tempValue | K1: test
A2: int | B2: int | C2: int | D2: unlocktype | E2: int | F2: int | G2: string | H2: string | I2: string | J2: string | K2: string
A3: all | B3: all | C3: client | D3: all | E3: all | F3: all | G3: client | H3: nodata | I3: client | J3: nodata | K3: nodata
A4: 1 | B4: 1 | C4: 1 | D4: 1 | E4: 1 | F4: 1 | G4: buy_coral | H4: 연약한 가지산호 필요 | J4: 1
A5: 2 | B5: 2 | C5: 2 | D5: 1 | E5: 1 | F5: 1 | G5: buy_coral | H5: 연약한 가지산호 필요 | J5: 1
A6: 3 | B6: 3 | C6: 3 | D6: 2 | E6: 0 | F6: 10 | G6: have_fish_kind | H6: 크라운 종 10마리 필요 | J6: 10
A7: 4 | B7: 4 | C7: 4 | D7: 4 | E7: 3 | F7: 5 | G7: have_fish | H7: 블루 크라운 5마리 보유 | J7: 5
A8: 5 | B8: 5 | C8: 5 | D8: 1 | E8: 2 | F8: 1 | G8: buy_coral | H8: 싱그러운 해초 필요 | J8: 1
A9: 6 | B9: 5 | C9: 6 | D9: 2 | E9: 0 | F9: 5 | G9: have_fish_kind | H9: 크라운 종 5마리 필요 | J9: 5
A10: 7 | B10: 6 | C10: 7 | D10: 1 | E10: 2 | F10: 1 | G10: buy_coral | H10: 싱그러운 해초 필요 | J10: 1
A11: 8 | B11: 6 | C11: 8 | D11: 2 | E11: 0 | F11: 5 | G11: have_fish_kind | H11: 크라운 종 5마리 필요 | J11: 5
A12: 9 | B12: 7 | C12: 9 | D12: 1 | E12: 2 | F12: 1 | G12: buy_coral | H12: 싱그러운 해초 필요 | J12: 1
A13: 10 | B13: 7 | C13: 10 | D13: 2 | E13: 0 | F13: 5 | G13: have_fish_kind | H13: 크라운 종 5마리 필요 | J13: 5
A14: 11 | B14: 8 | C14: 11 | D14: 16 | E14: 0 | F14: 10 | G14: daily_mission_clear | H14: 일일 미션 클리어하기 10회 | J14: 1 | K14: 일일 미션 클리어하기 1회
A15: 12 | B15: 9 | C15: 12 | D15: 1 | E15: 3 | F15: 1 | G15: buy_coral | H15: 붉은 부채산호 필요 | J15: 1
A16: 13 | B16: 9 | C16: 13 | D16: 2 | E16: 0 | F16: 5 | G16: have_fish_kind | H16: 크라운 종 5마리 필요 | J16: 5
A17: 14 | B17: 10 | C17: 14 | D17: 1 | E17: 3 | F17: 1 | G17: buy_coral | H17: 붉은 부채산호 필요 | J17: 1
A18: 15 | B18: 10 | C18: 15 | D18: 2 | E18: 0 | F18: 5 | G18: have_fish_kind | H18: 크라운 종 5마리 필요 | J18: 5
A19: 16 | B19: 11 | C19: 16 | D19: 1 | E19: 4 | F19: 1 | G19: buy_coral | H19: 신비의 불가사리 필요 | J19: 1
A20: 17 | B20: 11 | C20: 17 | D20: 2 | E20: 1 | F20: 5 | G20: have_fish_kind | H20: 고비 종 5마리 필요 | J20: 5
A21: 18 | B21: 12 | C21: 18 | D21: 1 | E21: 4 | F21: 1 | G21: buy_coral | H21: 신비의 불가사리 필요 | J21: 1
A22: 19 | B22: 12 | C22: 19 | D22: 2 | E22: 1 | F22: 5 | G22: have_fish_kind | H22: 고비 종 5마리 필요 | J22: 5
A23: 20 | B23: 13 | C23: 20 | D23: 6 | E23: 0 | F23: 2 | G23: attendance_count | H23: 출석 2일 | J23: 1 | K23: 출석 1일
A24: 21 | B24: 14 | C24: 21 | D24: 1 | E24: 5 | F24: 1 | G24: buy_coral | H24: 새하얀 말미잘 필요 | J24: 1
A25: 22 | B25: 14 | C25: 22 | D25: 2 | E25: 1 | F25: 5 | G25: have_fish_kind | H25: 고비 종 5마리 필요 | J25: 5
A26: 23 | B26: 15 | C26: 23 | D26: 1 | E26: 5 | F26: 1 | G26: buy_coral | H26: 새하얀 말미잘 필요 | J26: 1
A27: 24 | B27: 15 | C27: 24 | D27: 2 | E27: 1 | F27: 5 | G27: have_fish_kind | H27: 고비 종 5마리 필요 | J27: 5
A28: 25 | B28: 16 | C28: 25 | D28: 34 | E28: 0 | F28: 1000 | G28: touch_stone | H28: 산호석 터치하기 1000회 | J28: 50 | K28: 산호석 터치하기 50 회
A29: 26 | B29: 17 | C29: 26 | D29: 2 | E29: 2 | F29: 50 | G29: have_fish_kind | H29: 탱 종 50마리 필요 | J29: 50
A30: 27 | B30: 18 | C30: 27 | D30: 16 | E30: 0 | F30: 25 | G30: daily_mission_clear | H30: 일일 미션 클리어하기 25회 | J30: 2 | K30: 일일 미션 클리어하기 2회
A31: 28 | B31: 19 | C31: 28 | D31: 1 | E31: 6 | F31: 1 | G31: buy_coral | H31: 진주빛 말미잘 필요 | J31: 1
A32: 29 | B32: 19 | C32: 29 | D32: 2 | E32: 2 | F32: 5 | G32: have_fish_kind | H32: 탱 종 5마리 필요 | J32: 5
A33: 30 | B33: 20 | C33: 30 | D33: 1 | E33: 6 | F33: 1 | G33: buy_coral | H33: 진주빛 말미잘 필요 | J33: 1
A34: 31 | B34: 20 | C34: 31 | D34: 2 | E34: 2 | F34: 5 | G34: have_fish_kind | H34: 탱 종 5마리 필요 | J34: 5
A35: 32 | B35: 21 | C35: 32 | D35: 9 | E35: 1 | F35: 5 | G35: skill_levelup | H35: 화산 폭발스킬 5 레벨 달성 | J35: 5
A36: 33 | B36: 22 | C36: 33 | D36: 1 | E36: 6 | F36: 1 | G36: buy_coral | H36: 진주빛 말미잘 필요 | J36: 1
A37: 34 | B37: 22 | C37: 34 | D37: 2 | E37: 2 | F37: 5 | G37: have_fish_kind | H37: 탱 종 5마리 필요 | J37: 5
A38: 35 | B38: 23 | C38: 35 | D38: 1 | E38: 6 | F38: 1 | G38: buy_coral | H38: 진주빛 말미잘 필요 | J38: 1
A39: 36 | B39: 23 | C39: 36 | D39: 2 | E39: 2 | F39: 5 | G39: have_fish_kind | H39: 탱 종 5마리 필요 | J39: 5
A40: 37 | B40: 24 | C40: 37 | D40: 80 | E40: 0 | F40: 500 | G40: use_gem | H40: 보석 사용하기 500개 | J40: 500
...

Sheet FishGroup
A1: Id | B1: FName | C1: GroupName
A2: int | B2: string | C2: string
A3: client | B3: nodata | C3: client
A4: 0 | B4: 크라운 | C4: ="fishkind_"&A4 -> fishkind_0
A5: 1 | B5: 고비 | C5: ="fishkind_"&A5 -> fishkind_1
A6: 2 | B6: 탱 | C6: ="fishkind_"&A6 -> fishkind_2
A7: 3 | B7: 담셀 | C7: ="fishkind_"&A7 -> fishkind_3
A8: 4 | B8: 앤젤 | C8: ="fishkind_"&A8 -> fishkind_4
A9: 5 | B9: 놀래기 | C9: ="fishkind_"&A9 -> fishkind_5
A10: 6 | B10: 도티백 | C10: ="fishkind_"&A10 -> fishkind_6
A11: 7 | B11: 나비 | C11: ="fishkind_"&A11 -> fishkind_7
A12: 8 | B12: 패럿피쉬 | C12: ="fishkind_"&A12 -> fishkind_8
A13: 9 | B13: 복어 | C13: ="fishkind_"&A13 -> fishkind_9
A14: 10 | B14: 해마 | C14: ="fishkind_"&A14 -> fishkind_10
A15: 11 | B15: 해파리 | C15: ="fishkind_"&A15 -> fishkind_11
... A32: 999 | B32: 기타 | C32: ="fishkind_"&A32 -> fishkind_999
